Traceback (most recent call last):
  File "/homeappl/home/aliagadi/appl_taito/miniconda3/envs/b36backup/lib/python3.6/site-packages/IPython/core/history.py", line 87, in catch_corrupt_db
    return f(self, *a, **kw)
  File "/homeappl/home/aliagadi/appl_taito/miniconda3/envs/b36backup/lib/python3.6/site-packages/IPython/core/history.py", line 260, in init_db
    PRIMARY KEY (session, line))""")
sqlite3.OperationalError: attempt to write a readonly database

During handling of the above exception, another exception occurred:

Traceback (most recent call last):
  File "/homeappl/home/aliagadi/appl_taito/miniconda3/envs/b36backup/lib/python3.6/site-packages/IPython/core/history.py", line 87, in catch_corrupt_db
    return f(self, *a, **kw)
  File "/homeappl/home/aliagadi/appl_taito/miniconda3/envs/b36backup/lib/python3.6/site-packages/IPython/core/history.py", line 257, in init_db
    end timestamp, num_cmds integer, remark text)""")
sqlite3.OperationalError: disk I/O error

During handling of the above exception, another exception occurred:

Traceback (most recent call last):
  File "/homeappl/home/aliagadi/saltena_2018/flexpart_management/flexpart_management/notebooks/log_pol_revisited/log_pol_revisited_log_pol_taito.py", line 17, in <module>
    import flexpart_management.notebooks.log_pol_revisited. \
  File "/homeappl/home/aliagadi/saltena_2018/flexpart_management/flexpart_management/notebooks/log_pol_revisited/log_pol_revisited_lfc.py", line 17, in <module>
    from useful_scit.imps import *
  File "/homeappl/home/aliagadi/useful-scit/useful_scit/imps/__init__.py", line 47, in <module>
    set_matplotlib_formats('png')
  File "/homeappl/home/aliagadi/appl_taito/miniconda3/envs/b36backup/lib/python3.6/site-packages/IPython/core/display.py", line 1470, in set_matplotlib_formats
    shell = InteractiveShell.instance()
  File "/homeappl/home/aliagadi/appl_taito/miniconda3/envs/b36backup/lib/python3.6/site-packages/traitlets/config/configurable.py", line 412, in instance
    inst = cls(*args, **kwargs)
  File "/homeappl/home/aliagadi/appl_taito/miniconda3/envs/b36backup/lib/python3.6/site-packages/IPython/core/interactiveshell.py", line 661, in __init__
    self.init_history()
  File "/homeappl/home/aliagadi/appl_taito/miniconda3/envs/b36backup/lib/python3.6/site-packages/IPython/core/interactiveshell.py", line 1802, in init_history
    self.history_manager = HistoryManager(shell=self, parent=self)
  File "/homeappl/home/aliagadi/appl_taito/miniconda3/envs/b36backup/lib/python3.6/site-packages/IPython/core/history.py", line 537, in __init__
    **traits)
  File "/homeappl/home/aliagadi/appl_taito/miniconda3/envs/b36backup/lib/python3.6/site-packages/IPython/core/history.py", line 229, in __init__
    self.init_db()
  File "</homeappl/home/aliagadi/appl_taito/miniconda3/envs/b36backup/lib/python3.6/site-packages/decorator.py:decorator-gen-15>", line 2, in init_db
  File "/homeappl/home/aliagadi/appl_taito/miniconda3/envs/b36backup/lib/python3.6/site-packages/IPython/core/history.py", line 115, in catch_corrupt_db
    self.init_db()
  File "</homeappl/home/aliagadi/appl_taito/miniconda3/envs/b36backup/lib/python3.6/site-packages/decorator.py:decorator-gen-15>", line 2, in init_db
  File "/homeappl/home/aliagadi/appl_taito/miniconda3/envs/b36backup/lib/python3.6/site-packages/IPython/core/history.py", line 113, in catch_corrupt_db
    os.rename(self.hist_file, newpath)
FileNotFoundError: [Errno 2] No such file or directory: '/homeappl/home/aliagadi/.ipython/profile_default/history.sqlite' -> '/homeappl/home/aliagadi/.ipython/profile_default/history-corrupt.sqlite'
srun: error: c902: task 0: Exited with exit code 1
srun: Terminating job step 46977821.0
